Workbook

Sheet Inicio
A1: 🍇 FAST AÇAÍ — CMV Padrão para Franquias Próprias
A2: Matéria-prima, coberturas e embalagens têm o MESMO preço em todas as lojas (compra centralizada da franquia) — só os custos fixos mudam de loja para loja.
B3: 👉 Para mostrar aos sócios, use a aba RESUMO — mesmos produtos e preços do cardápio, sem fórmulas visíveis. As demais abas são a engenharia por trás dos números.
B5: Como usar (ordem recomendada)
B6: 1. Insumos | C6: Preencha os preços: Bases (Açaí/Cupuaçu) pelo valor da caixa de 9L produzida pela franqueadora; Coberturas por pacote (30g calculado sozinho).
B7: 2. Embalagens | C7: Preencha o valor da caixa de copos 200/300/500ml, tampas e canudo.
B8: 3. Ficha_Tecnica | C8: Já vem pronta com as receitas dos 58 itens do cardápio real (Açaí em Ondas + 9 receitas, Linha Premium, Linha Tradicional, Milkshakes, Bebidas) — ajuste só se mudar alguma receita.
B9: 4. Rateio | C9: Uma coluna por loja: preencha aluguel, energia, água, funcionários etc. de cada quiosque.
B10: 5. Configuracoes | C10: Escolha a 'Loja Selecionada' e ajuste margem, impostos, taxa de cartão e comissão.
B11: 6. Receitas | C11: Preço praticado (do cardápio) x custo real, CMV e margem de cada item — 100% automático.
B12: 7. Abas por categoria | C12: Açaí em Ondas, Linha Premium, Linha Tradicional, Toppings, Milkshakes e Bebidas — mesma informação da Receitas, organizada por seção do cardápio (tamanhos lado a lado) e pronta para mostrar aos sócios.
B13: 8. Precificacao / Dashboard / Simulador | C13: Calculadora rápida, visão gerencial e testes de variação de preço.
B15: Para replicar para outra loja
B16: Como os insumos são iguais para todas as lojas, você NÃO precisa duplicar o arquivo: só renomeie uma coluna em branco da aba Rateio com o nome do novo quiosque, preencha os custos fixos dele e selecione essa loja em Configurações.
B18: Legenda de cores
B19: Texto azul | C19: Célula de entrada — preencha com o valor da nota fiscal.
B20: Texto preto | C20: Fórmula — calculada automaticamente, evite editar.
B21: Texto verde | C21: Link com valor de outra aba.
B22: 🟢 🟡 🔴 | C22: Semáforo de margem: saudável / atenção / abaixo da meta (aba Receitas).

Sheet Açaí em Ondas
A1: 🍇 AÇAÍ EM ONDAS & RECEITAS FAST — Preço x Custo por Tamanho
A2: Compare o mesmo copo (P/M/G) lado a lado. Preço, custo, CMV e margem vêm da aba Receitas — não precisa mexer em fórmula nenhuma aqui.
A4: Produto | B4: 200ml | F4: 300ml | J4: 500ml
B5: Preço (R$) | C5: Custo Total (R$) | D5: CMV (%) | E5: Margem (%) | F5: Preço (R$) | G5: Custo Total (R$) | H5: CMV (%) | I5: Margem (%) | J5: Preço (R$) | K5: Custo Total (R$) | L5: CMV (%) | M5: Margem (%)
A6: Açaí em Ondas | B6: =IFERROR(INDEX(Receitas_PrecoPraticado,MATCH("Açaí em Ondas 200ml",Receitas_Produto,0)),"") -> 16.9 | C6: =IFERROR(INDEX(Receitas_CustoTotalUnit,MATCH("Açaí em Ondas 200ml",Receitas_Produto,0)),"") -> 11.718619 | D6: =IFERROR(INDEX(Receitas_CMV,MATCH("Açaí em Ondas 200ml",Receitas_Produto,0)),"") -> 0.25504976 | E6: =IFERROR(INDEX(Receitas_Margem,MATCH("Açaí em Ondas 200ml",Receitas_Produto,0)),"") -> 0.1015906 | F6: =IFERROR(INDEX(Receitas_PrecoPraticado,MATCH("Açaí em Ondas 300ml",Receitas_Produto,0)),"") -> 22.9 | G6: =IFERROR(INDEX(Receitas_CustoTotalUnit,MATCH("Açaí em Ondas 300ml",Receitas_Produto,0)),"") -> 13.406165 | H6: =IFERROR(INDEX(Receitas_CMV,MATCH("Açaí em Ondas 300ml",Receitas_Produto,0)),"") -> 0.26191648 | I6: =IFERROR(INDEX(Receitas_Margem,MATCH("Açaí em Ondas 300ml",Receitas_Produto,0)),"") -> 0.20957794 | J6: =IFERROR(INDEX(Receitas_PrecoPraticado,MATCH("Açaí em Ondas 500ml",Receitas_Produto,0)),"") -> 29.9 | K6: =IFERROR(INDEX(Receitas_CustoTotalUnit,MATCH("Açaí em Ondas 500ml",Receitas_Produto,0)),"") -> 16.911248 | L6: =IFERROR(INDEX(Receitas_CMV,MATCH("Açaí em Ondas 500ml",Receitas_Produto,0)),"") -> 0.31782508 | M6: =IFERROR(INDEX(Receitas_Margem,MATCH("Açaí em Ondas 500ml",Receitas_Produto,0)),"") -> 0.22940643
A7: Fast Classic | B7: =IFERROR(INDEX(Receitas_PrecoPraticado,MATCH("Fast Classic 200ml",Receitas_Produto,0)),"") -> 16.9 | C7: =IFERROR(INDEX(Receitas_CustoTotalUnit,MATCH("Fast Classic 200ml",Receitas_Produto,0)),"") -> 12.756248 | D7: =IFERROR(INDEX(Receitas_CMV,MATCH("Fast Classic 200ml",Receitas_Produto,0)),"") -> 0.31644792 | E7: =IFERROR(INDEX(Receitas_Margem,MATCH("Fast Classic 200ml",Receitas_Produto,0)),"") -> 0.040192447 | F7: =IFERROR(INDEX(Receitas_PrecoPraticado,MATCH("Fast Classic 300ml",Receitas_Produto,0)),"") -> 22.9 | G7: =IFERROR(INDEX(Receitas_CustoTotalUnit,MATCH("Fast Classic 300ml",Receitas_Produto,0)),"") -> 14.443794 | H7: =IFERROR(INDEX(Receitas_CMV,MATCH("Fast Classic 300ml",Receitas_Produto,0)),"") -> 0.30722778 | I7: =IFERROR(INDEX(Receitas_Margem,MATCH("Fast Classic 300ml",Receitas_Produto,0)),"") -> 0.16426664 | J7: =IFERROR(INDEX(Receitas_PrecoPraticado,MATCH("Fast Classic 500ml",Receitas_Produto,0)),"") -> 29.9 | K7: =IFERROR(INDEX(Receitas_CustoTotalUnit,MATCH("Fast Classic 500ml",Receitas_Produto,0)),"") -> 17.948877 | L7: =IFERROR(INDEX(Receitas_CMV,MATCH("Fast Classic 500ml",Receitas_Produto,0)),"") -> 0.35252839 | M7: =IFERROR(INDEX(Receitas_Margem,MATCH("Fast Classic 500ml",Receitas_Produto,0)),"") -> 0.19470313
A8: Power | B8: =IFERROR(INDEX(Receitas_PrecoPraticado,MATCH("Power 200ml",Receitas_Produto,0)),"") -> 16.9 | C8: =IFERROR(INDEX(Receitas_CustoTotalUnit,MATCH("Power 200ml",Receitas_Produto,0)),"") -> 12.409237 | D8: =IFERROR(INDEX(Receitas_CMV,MATCH("Power 200ml",Receitas_Produto,0)),"") -> 0.29591477 | E8: =IFERROR(INDEX(Receitas_Margem,MATCH("Power 200ml",Receitas_Produto,0)),"") -> 0.060725602 | F8: =IFERROR(INDEX(Receitas_PrecoPraticado,MATCH("Power 300ml",Receitas_Produto,0)),"") -> 22.9 | G8: =IFERROR(INDEX(Receitas_CustoTotalUnit,MATCH("Power 300ml",Receitas_Produto,0)),"") -> 14.096784 | H8: =IFERROR(INDEX(Receitas_CMV,MATCH("Power 300ml",Receitas_Produto,0)),"") -> 0.2920745 | I8: =IFERROR(INDEX(Receitas_Margem,MATCH("Power 300ml",Receitas_Produto,0)),"") -> 0.17941992 | J8: =IFERROR(INDEX(Receitas_PrecoPraticado,MATCH("Power 500ml",Receitas_Produto,0)),"") -> 29.9 | K8: =IFERROR(INDEX(Receitas_CustoTotalUnit,MATCH("Power 500ml",Receitas_Produto,0)),"") -> 17.601866 | L8: =IFERROR(INDEX(Receitas_CMV,MATCH("Power 500ml",Receitas_Produto,0)),"") -> 0.34092269 | M8: =IFERROR(INDEX(Receitas_Margem,MATCH("Power 500ml",Receitas_Produto,0)),"") -> 0.20630882
A9: Choco Nuts | B9: =IFERROR(INDEX(Receitas_PrecoPraticado,MATCH("Choco Nuts 200ml",Receitas_Produto,0)),"") -> 16.9 | C9: =IFERROR(INDEX(Receitas_CustoTotalUnit,MATCH("Choco Nuts 200ml",Receitas_Produto,0)),"") -> 13.116628 | D9: =IFERROR(INDEX(Receitas_CMV,MATCH("Choco Nuts 200ml",Receitas_Produto,0)),"") -> 0.33777222 | E9: =IFERROR(INDEX(Receitas_Margem,MATCH("Choco Nuts 200ml",Receitas_Produto,0)),"") -> 0.018868148 | F9: =IFERROR(INDEX(Receitas_PrecoPraticado,MATCH("Choco Nuts 300ml",Receitas_Produto,0)),"") -> 22.9 | G9: =IFERROR(INDEX(Receitas_CustoTotalUnit,MATCH("Choco Nuts 300ml",Receitas_Produto,0)),"") -> 14.804175 | H9: =IFERROR(INDEX(Receitas_CMV,MATCH("Choco Nuts 300ml",Receitas_Produto,0)),"") -> 0.32296493 | I9: =IFERROR(INDEX(Receitas_Margem,MATCH("Choco Nuts 300ml",Receitas_Produto,0)),"") -> 0.14852949 | J9: =IFERROR(INDEX(Receitas_PrecoPraticado,MATCH("Choco Nuts 500ml",Receitas_Produto,0)),"") -> 29.9 | K9: =IFERROR(INDEX(Receitas_CustoTotalUnit,MATCH("Choco Nuts 500ml",Receitas_Produto,0)),"") -> 18.309257 | L9: =IFERROR(INDEX(Receitas_CMV,MATCH("Choco Nuts 500ml",Receitas_Produto,0)),"") -> 0.36458125 | M9: =IFERROR(INDEX(Receitas_Margem,MATCH("Choco Nuts 500ml",Receitas_Produto,0)),"") -> 0.18265026
A10: Trupe Fast | B10: =IFERROR(INDEX(Receitas_PrecoPraticado,MATCH("Trupe Fast 200ml",Receitas_Produto,0)),"") -> 16.9 | C10: =IFERROR(INDEX(Receitas_CustoTotalUnit,MATCH("Trupe Fast 200ml",Receitas_Produto,0)),"") -> 11.343464 | D10: =IFERROR(INDEX(Receitas_CMV,MATCH("Trupe Fast 200ml",Receitas_Produto,0)),"") -> 0.23285126 | E10: =IFERROR(INDEX(Receitas_Margem,MATCH("Trupe Fast 200ml",Receitas_Produto,0)),"") -> 0.1237891 | F10: =IFERROR(INDEX(Receitas_PrecoPraticado,MATCH("Trupe Fast 300ml",Receitas_Produto,0)),"") -> 22.9 | G10: =IFERROR(INDEX(Receitas_CustoTotalUnit,MATCH("Trupe Fast 300ml",Receitas_Produto,0)),"") -> 13.031011 | H10: =IFERROR(INDEX(Receitas_CMV,MATCH("Trupe Fast 300ml",Receitas_Produto,0)),"") -> 0.24553418 | I10: =IFERROR(INDEX(Receitas_Margem,MATCH("Trupe Fast 300ml",Receitas_Produto,0)),"") -> 0.22596024 | J10: =IFERROR(INDEX(Receitas_PrecoPraticado,MATCH("Trupe Fast 500ml",Receitas_Produto,0)),"") -> 29.9 | K10: =IFERROR(INDEX(Receitas_CustoTotalUnit,MATCH("Trupe Fast 500ml",Receitas_Produto,0)),"") -> 16.536093 | L10: =IFERROR(INDEX(Receitas_CMV,MATCH("Trupe Fast 500ml",Receitas_Produto,0)),"") -> 0.3052781 | M10: =IFERROR(INDEX(Receitas_Margem,MATCH("Trupe Fast 500ml",Receitas_Produto,0)),"") -> 0.24195341
A11: Berry | B11: =IFERROR(INDEX(Receitas_PrecoPraticado,MATCH("Berry 200ml",Receitas_Produto,0)),"") -> 16.9 | C11: =IFERROR(INDEX(Receitas_CustoTotalUnit,MATCH("Berry 200ml",Receitas_Produto,0)),"") -> 11.853773 | D11: =IFERROR(INDEX(Receitas_CMV,MATCH("Berry 200ml",Receitas_Produto,0)),"") -> 0.26304708 | E11: =IFERROR(INDEX(Receitas_Margem,MATCH("Berry 200ml",Receitas_Produto,0)),"") -> 0.093593289 | F11: =IFERROR(INDEX(Receitas_PrecoPraticado,MATCH("Berry 300ml",Receitas_Produto,0)),"") -> 22.9 | G11: =IFERROR(INDEX(Receitas_CustoTotalUnit,MATCH("Berry 300ml",Receitas_Produto,0)),"") -> 13.54132 | H11: =IFERROR(INDEX(Receitas_CMV,MATCH("Berry 300ml",Receitas_Produto,0)),"") -> 0.26781843 | I11: =IFERROR(INDEX(Receitas_Margem,MATCH("Berry 300ml",Receitas_Produto,0)),"") -> 0.20367599 | J11: =IFERROR(INDEX(Receitas_PrecoPraticado,MATCH("Berry 500ml",Receitas_Produto,0)),"") -> 29.9 | K11: =IFERROR(INDEX(Receitas_CustoTotalUnit,MATCH("Berry 500ml",Receitas_Produto,0)),"") -> 17.046402 | L11: =IFERROR(INDEX(Receitas_CMV,MATCH("Berry 500ml",Receitas_Produto,0)),"") -> 0.3223453 | M11: =IFERROR(INDEX(Receitas_Margem,MATCH("Berry 500ml",Receitas_Produto,0)),"") -> 0.22488621
A12: Granola Fit | B12: =IFERROR(INDEX(Receitas_PrecoPraticado,MATCH("Granola Fit 200ml",Receitas_Produto,0)),"") -> 16.9 | C12: =IFERROR(INDEX(Receitas_CustoTotalUnit,MATCH("Granola Fit 200ml",Receitas_Produto,0)),"") -> 12.034083 | D12: =IFERROR(INDEX(Receitas_CMV,MATCH("Granola Fit 200ml",Receitas_Produto,0)),"") -> 0.27371627 | E12: =IFERROR(INDEX(Receitas_Margem,MATCH("Granola Fit 200ml",Receitas_Produto,0)),"") -> 0.082924101 | F12: =IFERROR(INDEX(Receitas_PrecoPraticado,MATCH("Granola Fit 300ml",Receitas_Produto,0)),"") -> 22.9 | G12: =IFERROR(INDEX(Receitas_CustoTotalUnit,MATCH("Granola Fit 300ml",Receitas_Produto,0)),"") -> 13.721629 | H12: =IFERROR(INDEX(Receitas_CMV,MATCH("Granola Fit 300ml",Receitas_Produto,0)),"") -> 0.2756922 | I12: =IFERROR(INDEX(Receitas_Margem,MATCH("Granola Fit 300ml",Receitas_Produto,0)),"") -> 0.19580222 | J12: =IFERROR(INDEX(Receitas_PrecoPraticado,MATCH("Granola Fit 500ml",Receitas_Produto,0)),"") -> 29.9 | K12: =IFERROR(INDEX(Receitas_CustoTotalUnit,MATCH("Granola Fit 500ml",Receitas_Produto,0)),"") -> 17.226712 | L12: =IFERROR(INDEX(Receitas_CMV,MATCH("Granola Fit 500ml",Receitas_Produto,0)),"") -> 0.32837571 | M12: =IFERROR(INDEX(Receitas_Margem,MATCH("Granola Fit 500ml",Receitas_Produto,0)),"") -> 0.2188558
A13: Fast Protein | B13: =IFERROR(INDEX(Receitas_PrecoPraticado,MATCH("Fast Protein 200ml",Receitas_Produto,0)),"") -> 16.9 | C13: =IFERROR(INDEX(Receitas_CustoTotalUnit,MATCH("Fast Protein 200ml",Receitas_Produto,0)),"") -> 11.762536 | D13: =IFERROR(INDEX(Receitas_CMV,MATCH("Fast Protein 200ml",Receitas_Produto,0)),"") -> 0.25764843 | E13: =IFERROR(INDEX(Receitas_Margem,MATCH("Fast Protein 200ml",Receitas_Produto,0)),"") -> 0.098991935 | F13: =IFERROR(INDEX(Receitas_PrecoPraticado,MATCH("Fast Protein 300ml",Receitas_Produto,0)),"") -> 22.9 | G13: =IFERROR(INDEX(Receitas_CustoTotalUnit,MATCH("Fast Protein 300ml",Receitas_Produto,0)),"") -> 13.450083 | H13: =IFERROR(INDEX(Receitas_CMV,MATCH("Fast Protein 300ml",Receitas_Produto,0)),"") -> 0.26383428 | I13: =IFERROR(INDEX(Receitas_Margem,MATCH("Fast Protein 300ml",Receitas_Produto,0)),"") -> 0.20766014 | J13: =IFERROR(INDEX(Receitas_PrecoPraticado,MATCH("Fast Protein 500ml",Receitas_Produto,0)),"") -> 29.9 | K13: =IFERROR(INDEX(Receitas_CustoTotalUnit,MATCH("Fast Protein 500ml",Receitas_Produto,0)),"") -> 16.955165 | L13: =IFERROR(INDEX(Receitas_CMV,MATCH("Fast Protein 500ml",Receitas_Produto,0)),"") -> 0.31929389 | M13: =IFERROR(INDEX(Receitas_Margem,MATCH("Fast Protein 500ml",Receitas_Produto,0)),"") -> 0.22793762
A14: Berry Protein | B14: =IFERROR(INDEX(Receitas_PrecoPraticado,MATCH("Berry Protein 200ml",Receitas_Produto,0)),"") -> 16.9 | C14: =IFERROR(INDEX(Receitas_CustoTotalUnit,MATCH("Berry Protein 200ml",Receitas_Produto,0)),"") -> 11.782401 | D14: =IFERROR(INDEX(Receitas_CMV,MATCH("Berry Protein 200ml",Receitas_Produto,0)),"") -> 0.25882389 | E14: =IFERROR(INDEX(Receitas_Margem,MATCH("Berry Protein 200ml",Receitas_Produto,0)),"") -> 0.09781648 | F14: =IFERROR(INDEX(Receitas_PrecoPraticado,MATCH("Berry Protein 300ml",Receitas_Produto,0)),"") -> 22.9 | G14: =IFERROR(INDEX(Receitas_CustoTotalUnit,MATCH("Berry Protein 300ml",Receitas_Produto,0)),"") -> 13.469948 | H14: =IFERROR(INDEX(Receitas_CMV,MATCH("Berry Protein 300ml",Receitas_Produto,0)),"") -> 0.26470175 | I14: =IFERROR(INDEX(Receitas_Margem,MATCH("Berry Protein 300ml",Receitas_Produto,0)),"") -> 0.20679267 | J14: =IFERROR(INDEX(Receitas_PrecoPraticado,MATCH("Berry Protein 500ml",Receitas_Produto,0)),"") -> 29.9 | K14: =IFERROR(INDEX(Receitas_CustoTotalUnit,MATCH("Berry Protein 500ml",Receitas_Produto,0)),"") -> 16.97503 | L14: =IFERROR(INDEX(Receitas_CMV,MATCH("Berry Protein 500ml",Receitas_Produto,0)),"") -> 0.31995828 | M14: =IFERROR(INDEX(Receitas_Margem,MATCH("Berry Protein 500ml",Receitas_Produto,0)),"") -> 0.22727323
A15: Nuts Protein | B15: =IFERROR(INDEX(Receitas_PrecoPraticado,MATCH("Nuts Protein 200ml",Receitas_Produto,0)),"") -> 16.9 | C15: =IFERROR(INDEX(Receitas_CustoTotalUnit,MATCH("Nuts Protein 200ml",Receitas_Produto,0)),"") -> 10.724907 | D15: =IFERROR(INDEX(Receitas_CMV,MATCH("Nuts Protein 200ml",Receitas_Produto,0)),"") -> 0.19625028 | E15: =IFERROR(INDEX(Receitas_Margem,MATCH("Nuts Protein 200ml",Receitas_Produto,0)),"") -> 0.16039009 | F15: =IFERROR(INDEX(Receitas_PrecoPraticado,MATCH("Nuts Protein 300ml",Receitas_Produto,0)),"") -> 22.9 | G15: =IFERROR(INDEX(Receitas_CustoTotalUnit,MATCH("Nuts Protein 300ml",Receitas_Produto,0)),"") -> 12.412454 | H15: =IFERROR(INDEX(Receitas_CMV,MATCH("Nuts Protein 300ml",Receitas_Produto,0)),"") -> 0.21852297 | I15: =IFERROR(INDEX(Receitas_Margem,MATCH("Nuts Protein 300ml",Receitas_Produto,0)),"") -> 0.25297145 | J15: =IFERROR(INDEX(Receitas_PrecoPraticado,MATCH("Nuts Protein 500ml",Receitas_Produto,0)),"") -> 29.9 | K15: =IFERROR(INDEX(Receitas_CustoTotalUnit,MATCH("Nuts Protein 500ml",Receitas_Produto,0)),"") -> 15.917536 | L15: =IFERROR(INDEX(Receitas_CMV,MATCH("Nuts Protein 500ml",Receitas_Produto,0)),"") -> 0.28459059 | M15: =IFERROR(INDEX(Receitas_Margem,MATCH("Nuts Protein 500ml",Receitas_Produto,0)),"") -> 0.26264093

Sheet Configuracoes
A1: ⚙️ CONFIGURAÇÕES — Parâmetros Globais de Precificação
A2: Edite apenas as células em AZUL. Estes parâmetros valem para TODAS as lojas — o que muda de loja para loja são os custos fixos, na aba Rateio. Escolha a loja ativa no campo 'Loja Selecionada' abaixo.
A4: Parâmetro | B4: Valor | C4: Observação
A5: Margem Bruta Desejada (%) | B5: 0.65 | C5: Referência de mercado para redes de açaí (60% a 70%).
A6: Margem Líquida Desejada (%) | B6: 0.15 | C6: Meta de lucro líquido após impostos, taxas e comissões.
A7: Impostos (%) | B7: 0.06 | C7: Alíquota efetiva estimada. Ajuste ao seu regime tributário.
A8: Taxa Cartão (%) | B8: 0.025 | C8: Taxa média de cartão/maquininha sobre o valor da venda.
A9: Comissão (%) | B9: 0.12 | C9: Comissão média de apps de delivery. Zere se vender só no balcão.
A10: Perdas (%) | B10: 0.03 | C10: Perda média de insumos (validade, erro de preparo), aplicada a todos os produtos.
A11: Desconto Máximo Permitido (%) | B11: 0.1 | C11: Limite de desconto em promoções sem corroer a margem mínima.
A12: Loja Ativa
A13: Loja Selecionada | B13: Loja 1 | C13: Define de qual loja (aba Rateio) vêm os custos fixos usados no CMV e no preço sugerido.

Sheet Insumos
A1: 🍇 INSUMOS — Preencha os Preços de Acordo com a Nota Fiscal
A2: BASES (Açaí/Cupuaçu): produzidas pela franqueadora e enviadas ao quiosque em caixa de calda pronta (padrão 9L) — confirme a Quantidade Comprada (ml da caixa) e digite o Valor Pago = valor cobrado pela caixa. COBERTURAS (30g): informe o valor pago e o peso do pacote comprado — o custo da porção de 30g é calculado sozinho na última coluna.
A4: Ingrediente | B4: Categoria | C4: Fornecedor | D4: Unidade | E4: Porção Padrão | F4: Quantidade Comprada | G4: Valor Pago (R$) | H4: Frete (R$) | I4: Valor Final (R$) | J4: Custo por g/ml/un (R$) | K4: Status | L4: Custo da Porção 30g (R$)
A5: Açaí | B5: Bases (Produção Própria) | D5: ml | E5: Caixa de 9L | F5: 9000 | G5: 148.5 | H5: 0 | I5: =IF(AND($G5="",$H5=""),"",SUM($G5:$H5)) -> 148.5 | J5: =IF($B5="","",IF($B5="Embalagens",IFERROR(INDEX(Embalagens_CustoUnit,MATCH($A5,Embalagens_Nome,0)),0),IFERROR($I5/$F5,0))) -> 0.0165 | K5: Ativo | L5: =IF($B5="Coberturas (30g)",IF($D5="un",$J5,$J5*30),"")
A6: Cupuaçu | B6: Bases (Produção Própria) | D6: ml | E6: Caixa de 9L | F6: 9000 | G6: 148.5 | H6: 0 | I6: =IF(AND($G6="",$H6=""),"",SUM($G6:$H6)) -> 148.5 | J6: =IF($B6="","",IF($B6="Embalagens",IFERROR(INDEX(Embalagens_CustoUnit,MATCH($A6,Embalagens_Nome,0)),0),IFERROR($I6/$F6,0))) -> 0.0165 | K6: Ativo | L6: =IF($B6="Coberturas (30g)",IF($D6="un",$J6,$J6*30),"")
A7: Leite Integral (Milkshake) | B7: Bases (Produção Própria) | D7: ml | E7: Caixa de 1L | F7: 1000 | H7: 0 | I7: =IF(AND($G7="",$H7=""),"",SUM($G7:$H7)) -> 0 | J7: =IF($B7="","",IF($B7="Embalagens",IFERROR(INDEX(Embalagens_CustoUnit,MATCH($A7,Embalagens_Nome,0)),0),IFERROR($I7/$F7,0))) -> 0 | K7: Ativo | L7: =IF($B7="Coberturas (30g)",IF($D7="un",$J7,$J7*30),"")
A8: Leite em pó | B8: Coberturas (30g) | D8: g | E8: 30g | F8: 1000 | G8: 33.55 | I8: =IF(AND($G8="",$H8=""),"",SUM($G8:$H8)) -> 33.55 | J8: =IF($B8="","",IF($B8="Embalagens",IFERROR(INDEX(Embalagens_CustoUnit,MATCH($A8,Embalagens_Nome,0)),0),IFERROR($I8/$F8,0))) -> 0.03355 | K8: Ativo | L8: =IF($B8="Coberturas (30g)",IF($D8="un",$J8,$J8*30),"") -> 1.0065
A9: Banana | B9: Coberturas (30g) | D9: g | E9: 30g | F9: 390000 | G9: 900 | I9: =IF(AND($G9="",$H9=""),"",SUM($G9:$H9)) -> 900 | J9: =IF($B9="","",IF($B9="Embalagens",IFERROR(INDEX(Embalagens_CustoUnit,MATCH($A9,Embalagens_Nome,0)),0),IFERROR($I9/$F9,0))) -> 0.0023076923 | K9: Ativo | L9: =IF($B9="Coberturas (30g)",IF($D9="un",$J9,$J9*30),"") -> 0.069230769
A10: Morango | B10: Coberturas (30g) | D10: g | E10: 30g | F10: 5000 | G10: 82.5 | I10: =IF(AND($G10="",$H10=""),"",SUM($G10:$H10)) -> 82.5 | J10: =IF($B10="","",IF($B10="Embalagens",IFERROR(INDEX(Embalagens_CustoUnit,MATCH($A10,Embalagens_Nome,0)),0),IFERROR($I10/$F10,0))) -> 0.0165 | K10: Ativo | L10: =IF($B10="Coberturas (30g)",IF($D10="un",$J10,$J10*30),"") -> 0.495
A11: Granola | B11: Coberturas (30g) | D11: g | E11: 30g | F11: 1000 | G11: 20 | I11: =IF(AND($G11="",$H11=""),"",SUM($G11:$H11)) -> 20 | J11: =IF($B11="","",IF($B11="Embalagens",IFERROR(INDEX(Embalagens_CustoUnit,MATCH($A11,Embalagens_Nome,0)),0),IFERROR($I11/$F11,0))) -> 0.02 | K11: Ativo | L11: =IF($B11="Coberturas (30g)",IF($D11="un",$J11,$J11*30),"") -> 0.6
A12: Leite condensado | B12: Coberturas (30g) | D12: g | E12: 30g | F12: 1000 | G12: 12.13 | I12: =IF(AND($G12="",$H12=""),"",SUM($G12:$H12)) -> 12.13 | J12: =IF($B12="","",IF($B12="Embalagens",IFERROR(INDEX(Embalagens_CustoUnit,MATCH($A12,Embalagens_Nome,0)),0),IFERROR($I12/$F12,0))) -> 0.01213 | K12: Ativo | L12: =IF($B12="Coberturas (30g)",IF($D12="un",$J12,$J12*30),"") -> 0.3639
A13: Paçoca | B13: Coberturas (30g) | D13: g | E13: 30g | F13: 1000 | G13: 22.33 | I13: =IF(AND($G13="",$H13=""),"",SUM($G13:$H13)) -> 22.33 | J13: =IF($B13="","",IF($B13="Embalagens",IFERROR(INDEX(Embalagens_CustoUnit,MATCH($A13,Embalagens_Nome,0)),0),IFERROR($I13/$F13,0))) -> 0.02233 | K13: Ativo | L13: =IF($B13="Coberturas (30g)",IF($D13="un",$J13,$J13*30),"") -> 0.6699
A14: Aveia | B14: Coberturas (30g) | D14: g | E14: 30g | F14: 1000 | I14: =IF(AND($G14="",$H14=""),"",SUM($G14:$H14)) | J14: =IF($B14="","",IF($B14="Embalagens",IFERROR(INDEX(Embalagens_CustoUnit,MATCH($A14,Embalagens_Nome,0)),0),IFERROR($I14/$F14,0))) -> 0 | K14: Ativo | L14: =IF($B14="Coberturas (30g)",IF($D14="un",$J14,$J14*30),"") -> 0
A15: Ovomaltine | B15: Coberturas (30g) | D15: g | E15: 30g | F15: 1000 | G15: 53.2 | I15: =IF(AND($G15="",$H15=""),"",SUM($G15:$H15)) -> 53.2 | J15: =IF($B15="","",IF($B15="Embalagens",IFERROR(INDEX(Embalagens_CustoUnit,MATCH($A15,Embalagens_Nome,0)),0),IFERROR($I15/$F15,0))) -> 0.0532 | K15: Ativo | L15: =IF($B15="Coberturas (30g)",IF($D15="un",$J15,$J15*30),"") -> 1.596
A16: Amendoim Granulado | B16: Coberturas (30g) | D16: g | E16: 30g | F16: 1000 | G16: 20.34 | I16: =IF(AND($G16="",$H16=""),"",SUM($G16:$H16)) -> 20.34 | J16: =IF($B16="","",IF($B16="Embalagens",IFERROR(INDEX(Embalagens_CustoUnit,MATCH($A16,Embalagens_Nome,0)),0),IFERROR($I16/$F16,0))) -> 0.02034 | K16: Ativo | L16: =IF($B16="Coberturas (30g)",IF($D16="un",$J16,$J16*30),"") -> 0.6102
A17: Pastilha de Chocolate | B17: Coberturas (30g) | D17: g | E17: 30g | F17: 1000 | G17: 29.59 | I17: =IF(AND($G17="",$H17=""),"",SUM($G17:$H17)) -> 29.59 | J17: =IF($B17="","",IF($B17="Embalagens",IFERROR(INDEX(Embalagens_CustoUnit,MATCH($A17,Embalagens_Nome,0)),0),IFERROR($I17/$F17,0))) -> 0.02959 | K17: Ativo | L17: =IF($B17="Coberturas (30g)",IF($D17="un",$J17,$J17*30),"") -> 0.8877
A18: Calda de Morango | B18: Coberturas (30g) | D18: ml | E18: 30ml | F18: 1000 | I18: =IF(AND($G18="",$H18=""),"",SUM($G18:$H18)) | J18: =IF($B18="","",IF($B18="Embalagens",IFERROR(INDEX(Embalagens_CustoUnit,MATCH($A18,Embalagens_Nome,0)),0),IFERROR($I18/$F18,0))) -> 0 | K18: Ativo | L18: =IF($B18="Coberturas (30g)",IF($D18="un",$J18,$J18*30),"") -> 0
A19: Calda de Maracujá | B19: Coberturas (30g) | D19: ml | E19: 30ml | F19: 1000 | I19: =IF(AND($G19="",$H19=""),"",SUM($G19:$H19)) | J19: =IF($B19="","",IF($B19="Embalagens",IFERROR(INDEX(Embalagens_CustoUnit,MATCH($A19,Embalagens_Nome,0)),0),IFERROR($I19/$F19,0))) -> 0 | K19: Ativo | L19: =IF($B19="Coberturas (30g)",IF($D19="un",$J19,$J19*30),"") -> 0
A20: Calda de Avelã | B20: Coberturas (30g) | D20: ml | E20: 30ml | I20: =IF(AND($G20="",$H20=""),"",SUM($G20:$H20)) | J20: =IF($B20="","",IF($B20="Embalagens",IFERROR(INDEX(Embalagens_CustoUnit,MATCH($A20,Embalagens_Nome,0)),0),IFERROR($I20/$F20,0))) -> 0 | K20: Ativo | L20: =IF($B20="Coberturas (30g)",IF($D20="un",$J20,$J20*30),"") -> 0
A21: Mel | B21: Coberturas (30g) | D21: ml | E21: 30ml | F21: 1000 | I21: =IF(AND($G21="",$H21=""),"",SUM($G21:$H21)) | J21: =IF($B21="","",IF($B21="Embalagens",IFERROR(INDEX(Embalagens_CustoUnit,MATCH($A21,Embalagens_Nome,0)),0),IFERROR($I21/$F21,0))) -> 0 | K21: Ativo | L21: =IF($B21="Coberturas (30g)",IF($D21="un",$J21,$J21*30),"") -> 0
A22: Whey Protein | B22: Coberturas (30g) | D22: g | E22: 30g | F22: 1000 | I22: =IF(AND($G22="",$H22=""),"",SUM($G22:$H22)) | J22: =IF($B22="","",IF($B22="Embalagens",IFERROR(INDEX(Embalagens_CustoUnit,MATCH($A22,Embalagens_Nome,0)),0),IFERROR($I22/$F22,0))) -> 0 | K22: Ativo | L22: =IF($B22="Coberturas (30g)",IF($D22="un",$J22,$J22*30),"") -> 0
A23: Nutella | B23: Coberturas (30g) | D23: g | E23: 30g | F23: 1000 | I23: =IF(AND($G23="",$H23=""),"",SUM($G23:$H23)) | J23: =IF($B23="","",IF($B23="Embalagens",IFERROR(INDEX(Embalagens_CustoUnit,MATCH($A23,Embalagens_Nome,0)),0),IFERROR($I23/$F23,0))) -> 0 | K23: Ativo | L23: =IF($B23="Coberturas (30g)",IF($D23="un",$J23,$J23*30),"") -> 0
A24: Pasta de Amendoim | B24: Coberturas (30g) | D24: g | E24: 30g | F24: 1000 | I24: =IF(AND($G24="",$H24=""),"",SUM($G24:$H24)) | J24: =IF($B24="","",IF($B24="Embalagens",IFERROR(INDEX(Embalagens_CustoUnit,MATCH($A24,Embalagens_Nome,0)),0),IFERROR($I24/$F24,0))) -> 0 | K24: Ativo | L24: =IF($B24="Coberturas (30g)",IF($D24="un",$J24,$J24*30),"") -> 0
A25: Canudo Wafer | B25: Coberturas (30g) | D25: un | E25: 1 unidade | F25: 1000 | I25: =IF(AND($G25="",$H25=""),"",SUM($G25:$H25)) | J25: =IF($B25="","",IF($B25="Embalagens",IFERROR(INDEX(Embalagens_CustoUnit,MATCH($A25,Embalagens_Nome,0)),0),IFERROR($I25/$F25,0))) -> 0 | K25: Ativo | L25: =IF($B25="Coberturas (30g)",IF($D25="un",$J25,$J25*30),"") -> 0
A26: Copo 200ml | B26: Embalagens | D26: un | E26: ver aba Embalagens | F26: 1 | G26: 0.1668 | I26: =IF(AND($G26="",$H26=""),"",SUM($G26:$H26)) -> 0.1668 | J26: =IF($B26="","",IF($B26="Embalagens",IFERROR(INDEX(Embalagens_CustoUnit,MATCH($A26,Embalagens_Nome,0)),0),IFERROR($I26/$F26,0))) -> 0.1668 | K26: Ativo | L26: =IF($B26="Coberturas (30g)",IF($D26="un",$J26,$J26*30),"")
A27: Copo 300ml | B27: Embalagens | D27: un | E27: ver aba Embalagens | F27: 1 | G27: 0.15372 | I27: =IF(AND($G27="",$H27=""),"",SUM($G27:$H27)) -> 0.15372 | J27: =IF($B27="","",IF($B27="Embalagens",IFERROR(INDEX(Embalagens_CustoUnit,MATCH($A27,Embalagens_Nome,0)),0),IFERROR($I27/$F27,0))) -> 0.15372 | K27: Ativo | L27: =IF($B27="Coberturas (30g)",IF($D27="un",$J27,$J27*30),"")
A28: Copo 500ml | B28: Embalagens | D28: un | E28: ver aba Embalagens | F28: 1 | G28: 0.24365 | I28: =IF(AND($G28="",$H28=""),"",SUM($G28:$H28)) -> 0.24365 | J28: =IF($B28="","",IF($B28="Embalagens",IFERROR(INDEX(Embalagens_CustoUnit,MATCH($A28,Embalagens_Nome,0)),0),IFERROR($I28/$F28,0))) -> 0.24365 | K28: Ativo | L28: =IF($B28="Coberturas (30g)",IF($D28="un",$J28,$J28*30),"")
A29: Tampa 200ml | B29: Embalagens | D29: un | E29: ver aba Embalagens | F29: 1 | G29: 0.0823 | I29: =IF(AND($G29="",$H29=""),"",SUM($G29:$H29)) -> 0.0823 | J29: =IF($B29="","",IF($B29="Embalagens",IFERROR(INDEX(Embalagens_CustoUnit,MATCH($A29,Embalagens_Nome,0)),0),IFERROR($I29/$F29,0))) -> 0.0823 | K29: Ativo | L29: =IF($B29="Coberturas (30g)",IF($D29="un",$J29,$J29*30),"")
A30: Tampa 300ml | B30: Embalagens | D30: un | E30: ver aba Embalagens | F30: 1 | G30: 0.0823 | I30: =IF(AND($G30="",$H30=""),"",SUM($G30:$H30)) -> 0.0823 | J30: =IF($B30="","",IF($B30="Embalagens",IFERROR(INDEX(Embalagens_CustoUnit,MATCH($A30,Embalagens_Nome,0)),0),IFERROR($I30/$F30,0))) -> 0.0823 | K30: Ativo | L30: =IF($B30="Coberturas (30g)",IF($D30="un",$J30,$J30*30),"")
A31: Tampa 500ml | B31: Embalagens | D31: un | E31: ver aba Embalagens | F31: 1 | G31: 0.0923 | I31: =IF(AND($G31="",$H31=""),"",SUM($G31:$H31)) -> 0.0923 | J31: =IF($B31="","",IF($B31="Embalagens",IFERROR(INDEX(Embalagens_CustoUnit,MATCH($A31,Embalagens_Nome,0)),0),IFERROR($I31/$F31,0))) -> 0.0923 | K31: Ativo | L31: =IF($B31="Coberturas (30g)",IF($D31="un",$J31,$J31*30),"")
A32: Copo Milkshake | B32: Embalagens | D32: un | E32: ver aba Embalagens | I32: =IF(AND($G32="",$H32=""),"",SUM($G32:$H32)) | J32: =IF($B32="","",IF($B32="Embalagens",IFERROR(INDEX(Embalagens_CustoUnit,MATCH($A32,Embalagens_Nome,0)),0),IFERROR($I32/$F32,0))) -> 0 | K32: Ativo | L32: =IF($B32="Coberturas (30g)",IF($D32="un",$J32,$J32*30),"")
A33: Tampa Milkshake | B33: Embalagens | D33: un | E33: ver aba Embalagens | I33: =IF(AND($G33="",$H33=""),"",SUM($G33:$H33)) | J33: =IF($B33="","",IF($B33="Embalagens",IFERROR(INDEX(Embalagens_CustoUnit,MATCH($A33,Embalagens_Nome,0)),0),IFERROR($I33/$F33,0))) -> 0 | K33: Ativo | L33: =IF($B33="Coberturas (30g)",IF($D33="un",$J33,$J33*30),"")
A34: Canudo | B34: Embalagens | D34: un | E34: ver aba Embalagens | I34: =IF(AND($G34="",$H34=""),"",SUM($G34:$H34)) | J34: =IF($B34="","",IF($B34="Embalagens",IFERROR(INDEX(Embalagens_CustoUnit,MATCH($A34,Embalagens_Nome,0)),0),IFERROR($I34/$F34,0))) -> 0 | K34: Ativo | L34: =IF($B34="Coberturas (30g)",IF($D34="un",$J34,$J34*30),"")
A35: Açaí Zero Açúcar 250ml | B35: Linha Premium (Comprada) | D35: un | E35: 1 pote | F35: 1 | G35: 12 | H35: 0 | I35: =IF(AND($G35="",$H35=""),"",SUM($G35:$H35)) -> 12 | J35: =IF($B35="","",IF($B35="Embalagens",IFERROR(INDEX(Embalagens_CustoUnit,MATCH($A35,Embalagens_Nome,0)),0),IFERROR($I35/$F35,0))) -> 12 | K35: Ativo | L35: =IF($B35="Coberturas (30g)",IF($D35="un",$J35,$J35*30),"")
A36: Açaí Zero Açúcar 500ml | B36: Linha Premium (Comprada) | D36: un | E36: 1 pote | F36: 1 | G36: 16 | H36: 0 | I36: =IF(AND($G36="",$H36=""),"",SUM($G36:$H36)) -> 16 | J36: =IF($B36="","",IF($B36="Embalagens",IFERROR(INDEX(Embalagens_CustoUnit,MATCH($A36,Embalagens_Nome,0)),0),IFERROR($I36/$F36,0))) -> 16 | K36: Ativo | L36: =IF($B36="Coberturas (30g)",IF($D36="un",$J36,$J36*30),"")
A37: Açaí Puro 250ml | B37: Linha Premium (Comprada) | D37: un | E37: 1 pote | F37: 1 | G37: 10 | H37: 0 | I37: =IF(AND($G37="",$H37=""),"",SUM($G37:$H37)) -> 10 | J37: =IF($B37="","",IF($B37="Embalagens",IFERROR(INDEX(Embalagens_CustoUnit,MATCH($A37,Embalagens_Nome,0)),0),IFERROR($I37/$F37,0))) -> 10 | K37: Ativo | L37: =IF($B37="Coberturas (30g)",IF($D37="un",$J37,$J37*30),"")
A38: Açaí Puro 500ml | B38: Linha Premium (Comprada) | D38: un | E38: 1 pote | F38: 1 | G38: 15 | H38: 0 | I38: =IF(AND($G38="",$H38=""),"",SUM($G38:$H38)) -> 15 | J38: =IF($B38="","",IF($B38="Embalagens",IFERROR(INDEX(Embalagens_CustoUnit,MATCH($A38,Embalagens_Nome,0)),0),IFERROR($I38/$F38,0))) -> 15 | K38: Ativo | L38: =IF($B38="Coberturas (30g)",IF($D38="un",$J38,$J38*30),"")
A39: Açaí Banana 250ml | B39: Linha Premium (Comprada) | D39: un | E39: 1 pote | F39: 1 | G39: 10 | H39: 0 | I39: =IF(AND($G39="",$H39=""),"",SUM($G39:$H39)) -> 10 | J39: =IF($B39="","",IF($B39="Embalagens",IFERROR(INDEX(Embalagens_CustoUnit,MATCH($A39,Embalagens_Nome,0)),0),IFERROR($I39/$F39,0))) -> 10 | K39: Ativo | L39: =IF($B39="Coberturas (30g)",IF($D39="un",$J39,$J39*30),"")
A40: Açaí Banana 500ml | B40: Linha Premium (Comprada) | D40: un | E40: 1 pote | F40: 1 | G40: 15 | H40: 0 | I40: =IF(AND($G40="",$H40=""),"",SUM($G40:$H40)) -> 15 | J40: =IF($B40="","",IF($B40="Embalagens",IFERROR(INDEX(Embalagens_CustoUnit,MATCH($A40,Embalagens_Nome,0)),0),IFERROR($I40/$F40,0))) -> 15 | K40: Ativo | L40: =IF($B40="Coberturas (30g)",IF($D40="un",$J40,$J40*30),"")
A41: Açaí Morango 250ml | B41: Linha Premium (Comprada) | D41: un | E41: 1 pote | F41: 1 | G41: 10 | H41: 0 | I41: =IF(AND($G41="",$H41=""),"",SUM($G41:$H41)) -> 10 | J41: =IF($B41="","",IF($B41="Embalagens",IFERROR(INDEX(Embalagens_CustoUnit,MATCH($A41,Embalagens_Nome,0)),0),IFERROR($I41/$F41,0))) -> 10 | K41: Ativo | L41: =IF($B41="Coberturas (30g)",IF($D41="un",$J41,$J41*30),"")
...

Sheet Embalagens
A1: 📦 EMBALAGENS — Copos 200/300/500ml, Tampas e Canudo
A2: Preencha Quantidade e Valor conforme a nota fiscal da caixa/pacote comprado (ex.: caixa com 1000 copos por R$ 175). O Custo Unitário é calculado sozinho e alimenta a aba Insumos.
A4: Nome | B4: Fornecedor | C4: Quantidade (un/caixa) | D4: Valor da Caixa (R$) | E4: Custo Unitário (R$)
A5: Copo 200ml | C5: 1 | D5: 0.1668 | E5: =IFERROR($D5/$C5,0) -> 0.1668
A6: Copo 300ml | C6: 1 | D6: 0.15372 | E6: =IFERROR($D6/$C6,0) -> 0.15372
A7: Copo 500ml | C7: 1 | D7: 0.24365 | E7: =IFERROR($D7/$C7,0) -> 0.24365
A8: Tampa 200ml | C8: 1 | D8: 0.0823 | E8: =IFERROR($D8/$C8,0) -> 0.0823
A9: Tampa 300ml | C9: 1 | D9: 0.0823 | E9: =IFERROR($D9/$C9,0) -> 0.0823
A10: Tampa 500ml | C10: 1 | D10: 0.0923 | E10: =IFERROR($D10/$C10,0) -> 0.0923
A11: Copo Milkshake | E11: =IFERROR($D11/$C11,0) -> 0
A12: Tampa Milkshake | E12: =IFERROR($D12/$C12,0) -> 0
A13: Canudo | E13: =IFERROR($D13/$C13,0) -> 0
E14: =IFERROR($D14/$C14,0) -> 0
E15: =IFERROR($D15/$C15,0) -> 0
E16: =IFERROR($D16/$C16,0) -> 0
E17: =IFERROR($D17/$C17,0) -> 0
E18: =IFERROR($D18/$C18,0) -> 0
E19: =IFERROR($D19/$C19,0) -> 0
E20: =IFERROR($D20/$C20,0) -> 0
E21: =IFERROR($D21/$C21,0) -> 0
E22: =IFERROR($D22/$C22,0) -> 0
E23: =IFERROR($D23/$C23,0) -> 0
E24: =IFERROR($D24/$C24,0) -> 0
E25: =IFERROR($D25/$C25,0) -> 0

Sheet Ficha_Tecnica
A1: 📋 FICHA TÉCNICA — Composição e Custo de Cada Produto
A2: Um ingrediente por linha. Açaí/Cupuaçu/Leite em ML; coberturas em múltiplos de 30g; embalagens em unidades. Para um NOVO PRODUTO, adicione linhas abaixo — nenhuma fórmula precisa ser alterada.
A4: Nome do Produto | B4: Categoria (auto) | C4: Ingrediente | D4: Quantidade Utilizada | E4: Unidade (auto) | F4: Custo Unitário (R$) | G4: Custo Total (R$) | H4: Qtd g/ml (aux.) | I4: Flag Açaí | J4: Flag Banana | K4: Flag Whey | L4: Flag Embalagem
A5: Açaí em Ondas 200ml | B5: =IF($C5="","",IFERROR(INDEX(Insumos_Categoria,MATCH($C5,Insumos_Ingrediente,0)),"")) -> Bases (Produção Própria) | C5: Açaí | D5: 170 | E5: =IF($C5="","",IFERROR(INDEX(Insumos_Unidade,MATCH($C5,Insumos_Ingrediente,0)),"")) -> ml | F5: =IFERROR(INDEX(Insumos_CustoUnit,MATCH($C5,Insumos_Ingrediente,0)),0) -> 0.0165 | G5: =$D5*$F5 -> 2.805 | H5: =IF(OR($E5="g",$E5="ml"),$D5,0) -> 170 | I5: =IF($C5="Açaí",1,0) -> 1 | J5: =IF($C5="Banana",1,0) -> 0 | K5: =IF($C5="Whey Protein",1,0) -> 0 | L5: =IF(ISNUMBER(SEARCH("Copo",$C5)),1,0) -> 0
A6: Açaí em Ondas 200ml | B6: =IF($C6="","",IFERROR(INDEX(Insumos_Categoria,MATCH($C6,Insumos_Ingrediente,0)),"")) -> Coberturas (30g) | C6: Banana | D6: 30 | E6: =IF($C6="","",IFERROR(INDEX(Insumos_Unidade,MATCH($C6,Insumos_Ingrediente,0)),"")) -> g | F6: =IFERROR(INDEX(Insumos_CustoUnit,MATCH($C6,Insumos_Ingrediente,0)),0) -> 0.0023076923 | G6: =$D6*$F6 -> 0.069230769 | H6: =IF(OR($E6="g",$E6="ml"),$D6,0) -> 30 | I6: =IF($C6="Açaí",1,0) -> 0 | J6: =IF($C6="Banana",1,0) -> 1 | K6: =IF($C6="Whey Protein",1,0) -> 0 | L6: =IF(ISNUMBER(SEARCH("Copo",$C6)),1,0) -> 0
A7: Açaí em Ondas 200ml | B7: =IF($C7="","",IFERROR(INDEX(Insumos_Categoria,MATCH($C7,Insumos_Ingrediente,0)),"")) -> Coberturas (30g) | C7: Granola | D7: 30 | E7: =IF($C7="","",IFERROR(INDEX(Insumos_Unidade,MATCH($C7,Insumos_Ingrediente,0)),"")) -> g | F7: =IFERROR(INDEX(Insumos_CustoUnit,MATCH($C7,Insumos_Ingrediente,0)),0) -> 0.02 | G7: =$D7*$F7 -> 0.6 | H7: =IF(OR($E7="g",$E7="ml"),$D7,0) -> 30 | I7: =IF($C7="Açaí",1,0) -> 0 | J7: =IF($C7="Banana",1,0) -> 0 | K7: =IF($C7="Whey Protein",1,0) -> 0 | L7: =IF(ISNUMBER(SEARCH("Copo",$C7)),1,0) -> 0
A8: Açaí em Ondas 200ml | B8: =IF($C8="","",IFERROR(INDEX(Insumos_Categoria,MATCH($C8,Insumos_Ingrediente,0)),"")) -> Coberturas (30g) | C8: Leite condensado | D8: 30 | E8: =IF($C8="","",IFERROR(INDEX(Insumos_Unidade,MATCH($C8,Insumos_Ingrediente,0)),"")) -> g | F8: =IFERROR(INDEX(Insumos_CustoUnit,MATCH($C8,Insumos_Ingrediente,0)),0) -> 0.01213 | G8: =$D8*$F8 -> 0.3639 | H8: =IF(OR($E8="g",$E8="ml"),$D8,0) -> 30 | I8: =IF($C8="Açaí",1,0) -> 0 | J8: =IF($C8="Banana",1,0) -> 0 | K8: =IF($C8="Whey Protein",1,0) -> 0 | L8: =IF(ISNUMBER(SEARCH("Copo",$C8)),1,0) -> 0
A9: Açaí em Ondas 200ml | B9: =IF($C9="","",IFERROR(INDEX(Insumos_Categoria,MATCH($C9,Insumos_Ingrediente,0)),"")) -> Embalagens | C9: Copo 200ml | D9: 1 | E9: =IF($C9="","",IFERROR(INDEX(Insumos_Unidade,MATCH($C9,Insumos_Ingrediente,0)),"")) -> un | F9: =IFERROR(INDEX(Insumos_CustoUnit,MATCH($C9,Insumos_Ingrediente,0)),0) -> 0.1668 | G9: =$D9*$F9 -> 0.1668 | H9: =IF(OR($E9="g",$E9="ml"),$D9,0) -> 0 | I9: =IF($C9="Açaí",1,0) -> 0 | J9: =IF($C9="Banana",1,0) -> 0 | K9: =IF($C9="Whey Protein",1,0) -> 0 | L9: =IF(ISNUMBER(SEARCH("Copo",$C9)),1,0) -> 1
A10: Açaí em Ondas 200ml | B10: =IF($C10="","",IFERROR(INDEX(Insumos_Categoria,MATCH($C10,Insumos_Ingrediente,0)),"")) -> Embalagens | C10: Tampa 200ml | D10: 1 | E10: =IF($C10="","",IFERROR(INDEX(Insumos_Unidade,MATCH($C10,Insumos_Ingrediente,0)),"")) -> un | F10: =IFERROR(INDEX(Insumos_CustoUnit,MATCH($C10,Insumos_Ingrediente,0)),0) -> 0.0823 | G10: =$D10*$F10 -> 0.0823 | H10: =IF(OR($E10="g",$E10="ml"),$D10,0) -> 0 | I10: =IF($C10="Açaí",1,0) -> 0 | J10: =IF($C10="Banana",1,0) -> 0 | K10: =IF($C10="Whey Protein",1,0) -> 0 | L10: =IF(ISNUMBER(SEARCH("Copo",$C10)),1,0) -> 0
A11: Açaí em Ondas 200ml | B11: =IF($C11="","",IFERROR(INDEX(Insumos_Categoria,MATCH($C11,Insumos_Ingrediente,0)),"")) -> Consumíveis | C11: Colher | D11: 1 | E11: =IF($C11="","",IFERROR(INDEX(Insumos_Unidade,MATCH($C11,Insumos_Ingrediente,0)),"")) -> un | F11: =IFERROR(INDEX(Insumos_CustoUnit,MATCH($C11,Insumos_Ingrediente,0)),0) -> 0.0938 | G11: =$D11*$F11 -> 0.0938 | H11: =IF(OR($E11="g",$E11="ml"),$D11,0) -> 0 | I11: =IF($C11="Açaí",1,0) -> 0 | J11: =IF($C11="Banana",1,0) -> 0 | K11: =IF($C11="Whey Protein",1,0) -> 0 | L11: =IF(ISNUMBER(SEARCH("Copo",$C11)),1,0) -> 0
A12: Açaí em Ondas 200ml | B12: =IF($C12="","",IFERROR(INDEX(Insumos_Categoria,MATCH($C12,Insumos_Ingrediente,0)),"")) -> Consumíveis | C12: Guardanapo | D12: 1 | E12: =IF($C12="","",IFERROR(INDEX(Insumos_Unidade,MATCH($C12,Insumos_Ingrediente,0)),"")) -> un | F12: =IFERROR(INDEX(Insumos_CustoUnit,MATCH($C12,Insumos_Ingrediente,0)),0) -> 0 | G12: =$D12*$F12 -> 0 | H12: =IF(OR($E12="g",$E12="ml"),$D12,0) -> 0 | I12: =IF($C12="Açaí",1,0) -> 0 | J12: =IF($C12="Banana",1,0) -> 0 | K12: =IF($C12="Whey Protein",1,0) -> 0 | L12: =IF(ISNUMBER(SEARCH("Copo",$C12)),1,0) -> 0
A13: Açaí em Ondas 300ml | B13: =IF($C13="","",IFERROR(INDEX(Insumos_Categoria,MATCH($C13,Insumos_Ingrediente,0)),"")) -> Bases (Produção Própria) | C13: Açaí | D13: 270 | E13: =IF($C13="","",IFERROR(INDEX(Insumos_Unidade,MATCH($C13,Insumos_Ingrediente,0)),"")) -> ml | F13: =IFERROR(INDEX(Insumos_CustoUnit,MATCH($C13,Insumos_Ingrediente,0)),0) -> 0.0165 | G13: =$D13*$F13 -> 4.455 | H13: =IF(OR($E13="g",$E13="ml"),$D13,0) -> 270 | I13: =IF($C13="Açaí",1,0) -> 1 | J13: =IF($C13="Banana",1,0) -> 0 | K13: =IF($C13="Whey Protein",1,0) -> 0 | L13: =IF(ISNUMBER(SEARCH("Copo",$C13)),1,0) -> 0
A14: Açaí em Ondas 300ml | B14: =IF($C14="","",IFERROR(INDEX(Insumos_Categoria,MATCH($C14,Insumos_Ingrediente,0)),"")) -> Coberturas (30g) | C14: Banana | D14: 30 | E14: =IF($C14="","",IFERROR(INDEX(Insumos_Unidade,MATCH($C14,Insumos_Ingrediente,0)),"")) -> g | F14: =IFERROR(INDEX(Insumos_CustoUnit,MATCH($C14,Insumos_Ingrediente,0)),0) -> 0.0023076923 | G14: =$D14*$F14 -> 0.069230769 | H14: =IF(OR($E14="g",$E14="ml"),$D14,0) -> 30 | I14: =IF($C14="Açaí",1,0) -> 0 | J14: =IF($C14="Banana",1,0) -> 1 | K14: =IF($C14="Whey Protein",1,0) -> 0 | L14: =IF(ISNUMBER(SEARCH("Copo",$C14)),1,0) -> 0
A15: Açaí em Ondas 300ml | B15: =IF($C15="","",IFERROR(INDEX(Insumos_Categoria,MATCH($C15,Insumos_Ingrediente,0)),"")) -> Coberturas (30g) | C15: Granola | D15: 30 | E15: =IF($C15="","",IFERROR(INDEX(Insumos_Unidade,MATCH($C15,Insumos_Ingrediente,0)),"")) -> g | F15: =IFERROR(INDEX(Insumos_CustoUnit,MATCH($C15,Insumos_Ingrediente,0)),0) -> 0.02 | G15: =$D15*$F15 -> 0.6 | H15: =IF(OR($E15="g",$E15="ml"),$D15,0) -> 30 | I15: =IF($C15="Açaí",1,0) -> 0 | J15: =IF($C15="Banana",1,0) -> 0 | K15: =IF($C15="Whey Protein",1,0) -> 0 | L15: =IF(ISNUMBER(SEARCH("Copo",$C15)),1,0) -> 0
A16: Açaí em Ondas 300ml | B16: =IF($C16="","",IFERROR(INDEX(Insumos_Categoria,MATCH($C16,Insumos_Ingrediente,0)),"")) -> Coberturas (30g) | C16: Leite condensado | D16: 30 | E16: =IF($C16="","",IFERROR(INDEX(Insumos_Unidade,MATCH($C16,Insumos_Ingrediente,0)),"")) -> g | F16: =IFERROR(INDEX(Insumos_CustoUnit,MATCH($C16,Insumos_Ingrediente,0)),0) -> 0.01213 | G16: =$D16*$F16 -> 0.3639 | H16: =IF(OR($E16="g",$E16="ml"),$D16,0) -> 30 | I16: =IF($C16="Açaí",1,0) -> 0 | J16: =IF($C16="Banana",1,0) -> 0 | K16: =IF($C16="Whey Protein",1,0) -> 0 | L16: =IF(ISNUMBER(SEARCH("Copo",$C16)),1,0) -> 0
... A373: Suco de Açaí 200ml | B373: =IF($C373="","",IFERROR(INDEX(Insumos_Categoria,MATCH($C373,Insumos_Ingrediente,0)),"")) -> Consumíveis | C373: Guardanapo | D373: 1 | E373: =IF($C373="","",IFERROR(INDEX(Insumos_Unidade,MATCH($C373,Insumos_Ingrediente,0)),"")) -> un | F373: =IFERROR(INDEX(Insumos_CustoUnit,MATCH($C373,Insumos_Ingrediente,0)),0) -> 0 | G373: =$D373*$F373 -> 0 | H373: =IF(OR($E373="g",$E373="ml"),$D373,0) -> 0 | I373: =IF($C373="Açaí",1,0) -> 0 | J373: =IF($C373="Banana",1,0) -> 0 | K373: =IF($C373="Whey Protein",1,0) -> 0 | L373: =IF(ISNUMBER(SEARCH("Copo",$C373)),1,0) -> 0
B374: =IF($C374="","",IFERROR(INDEX(Insumos_Categoria,MATCH($C374,Insumos_Ingrediente,0)),"")) | E374: =IF($C374="","",IFERROR(INDEX(Insumos_Unidade,MATCH($C374,Insumos_Ingrediente,0)),"")) | F374: =IFERROR(INDEX(Insumos_CustoUnit,MATCH($C374,Insumos_Ingrediente,0)),0) -> 0 | G374: =$D374*$F374 -> 0 | H374: =IF(OR($E374="g",$E374="ml"),$D374,0) -> 0 | I374: =IF($C374="Açaí",1,0) -> 0 | J374: =IF($C374="Banana",1,0) -> 0 | K374: =IF($C374="Whey Protein",1,0) -> 0 | L374: =IF(ISNUMBER(SEARCH("Copo",$C374)),1,0) -> 0
B375: =IF($C375="","",IFERROR(INDEX(Insumos_Categoria,MATCH($C375,Insumos_Ingrediente,0)),"")) | E375: =IF($C375="","",IFERROR(INDEX(Insumos_Unidade,MATCH($C375,Insumos_Ingrediente,0)),"")) | F375: =IFERROR(INDEX(Insumos_CustoUnit,MATCH($C375,Insumos_Ingrediente,0)),0) -> 0 | G375: =$D375*$F375 -> 0 | H375: =IF(OR($E375="g",$E375="ml"),$D375,0) -> 0 | I375: =IF($C375="Açaí",1,0) -> 0 | J375: =IF($C375="Banana",1,0) -> 0 | K375: =IF($C375="Whey Protein",1,0) -> 0 | L375: =IF(ISNUMBER(SEARCH("Copo",$C375)),1,0) -> 0
B376: =IF($C376="","",IFERROR(INDEX(Insumos_Categoria,MATCH($C376,Insumos_Ingrediente,0)),"")) | E376: =IF($C376="","",IFERROR(INDEX(Insumos_Unidade,MATCH($C376,Insumos_Ingrediente,0)),"")) | F376: =IFERROR(INDEX(Insumos_CustoUnit,MATCH($C376,Insumos_Ingrediente,0)),0) -> 0 | G376: =$D376*$F376 -> 0 | H376: =IF(OR($E376="g",$E376="ml"),$D376,0) -> 0 | I376: =IF($C376="Açaí",1,0) -> 0 | J376: =IF($C376="Banana",1,0) -> 0 | K376: =IF($C376="Whey Protein",1,0) -> 0 | L376: =IF(ISNUMBER(SEARCH("Copo",$C376)),1,0) -> 0
B377: =IF($C377="","",IFERROR(INDEX(Insumos_Categoria,MATCH($C377,Insumos_Ingrediente,0)),"")) | E377: =IF($C377="","",IFERROR(INDEX(Insumos_Unidade,MATCH($C377,Insumos_Ingrediente,0)),"")) | F377: =IFERROR(INDEX(Insumos_CustoUnit,MATCH($C377,Insumos_Ingrediente,0)),0) -> 0 | G377: =$D377*$F377 -> 0 | H377: =IF(OR($E377="g",$E377="ml"),$D377,0) -> 0 | I377: =IF($C377="Açaí",1,0) -> 0 | J377: =IF($C377="Banana",1,0) -> 0 | K377: =IF($C377="Whey Protein",1,0) -> 0 | L377: =IF(ISNUMBER(SEARCH("Copo",$C377)),1,0) -> 0
B378: =IF($C378="","",IFERROR(INDEX(Insumos_Categoria,MATCH($C378,Insumos_Ingrediente,0)),"")) | E378: =IF($C378="","",IFERROR(INDEX(Insumos_Unidade,MATCH($C378,Insumos_Ingrediente,0)),"")) | F378: =IFERROR(INDEX(Insumos_CustoUnit,MATCH($C378,Insumos_Ingrediente,0)),0) -> 0 | G378: =$D378*$F378 -> 0 | H378: =IF(OR($E378="g",$E378="ml"),$D378,0) -> 0 | I378: =IF($C378="Açaí",1,0) -> 0 | J378: =IF($C378="Banana",1,0) -> 0 | K378: =IF($C378="Whey Protein",1,0) -> 0 | L378: =IF(ISNUMBER(SEARCH("Copo",$C378)),1,0) -> 0
B379: =IF($C379="","",IFERROR(INDEX(Insumos_Categoria,MATCH($C379,Insumos_Ingrediente,0)),"")) | E379: =IF($C379="","",IFERROR(INDEX(Insumos_Unidade,MATCH($C379,Insumos_Ingrediente,0)),"")) | F379: =IFERROR(INDEX(Insumos_CustoUnit,MATCH($C379,Insumos_Ingrediente,0)),0) -> 0 | G379: =$D379*$F379 -> 0 | H379: =IF(OR($E379="g",$E379="ml"),$D379,0) -> 0 | I379: =IF($C379="Açaí",1,0) -> 0 | J379: =IF($C379="Banana",1,0) -> 0 | K379: =IF($C379="Whey Protein",1,0) -> 0 | L379: =IF(ISNUMBER(SEARCH("Copo",$C379)),1,0) -> 0
B380: =IF($C380="","",IFERROR(INDEX(Insumos_Categoria,MATCH($C380,Insumos_Ingrediente,0)),"")) | E380: =IF($C380="","",IFERROR(INDEX(Insumos_Unidade,MATCH($C380,Insumos_Ingrediente,0)),"")) | F380: =IFERROR(INDEX(Insumos_CustoUnit,MATCH($C380,Insumos_Ingrediente,0)),0) -> 0 | G380: =$D380*$F380 -> 0 | H380: =IF(OR($E380="g",$E380="ml"),$D380,0) -> 0 | I380: =IF($C380="Açaí",1,0) -> 0 | J380: =IF($C380="Banana",1,0) -> 0 | K380: =IF($C380="Whey Protein",1,0) -> 0 | L380: =IF(ISNUMBER(SEARCH("Copo",$C380)),1,0) -> 0
B381: =IF($C381="","",IFERROR(INDEX(Insumos_Categoria,MATCH($C381,Insumos_Ingrediente,0)),"")) | E381: =IF($C381="","",IFERROR(INDEX(Insumos_Unidade,MATCH($C381,Insumos_Ingrediente,0)),"")) | F381: =IFERROR(INDEX(Insumos_CustoUnit,MATCH($C381,Insumos_Ingrediente,0)),0) -> 0 | G381: =$D381*$F381 -> 0 | H381: =IF(OR($E381="g",$E381="ml"),$D381,0) -> 0 | I381: =IF($C381="Açaí",1,0) -> 0 | J381: =IF($C381="Banana",1,0) -> 0 | K381: =IF($C381="Whey Protein",1,0) -> 0 | L381: =IF(ISNUMBER(SEARCH("Copo",$C381)),1,0) -> 0
B382: =IF($C382="","",IFERROR(INDEX(Insumos_Categoria,MATCH($C382,Insumos_Ingrediente,0)),"")) | E382: =IF($C382="","",IFERROR(INDEX(Insumos_Unidade,MATCH($C382,Insumos_Ingrediente,0)),"")) | F382: =IFERROR(INDEX(Insumos_CustoUnit,MATCH($C382,Insumos_Ingrediente,0)),0) -> 0 | G382: =$D382*$F382 -> 0 | H382: =IF(OR($E382="g",$E382="ml"),$D382,0) -> 0 | I382: =IF($C382="Açaí",1,0) -> 0 | J382: =IF($C382="Banana",1,0) -> 0 | K382: =IF($C382="Whey Protein",1,0) -> 0 | L382: =IF(ISNUMBER(SEARCH("Copo",$C382)),1,0) -> 0
B383: =IF($C383="","",IFERROR(INDEX(Insumos_Categoria,MATCH($C383,Insumos_Ingrediente,0)),"")) | E383: =IF($C383="","",IFERROR(INDEX(Insumos_Unidade,MATCH($C383,Insumos_Ingrediente,0)),"")) | F383: =IFERROR(INDEX(Insumos_CustoUnit,MATCH($C383,Insumos_Ingrediente,0)),0) -> 0 | G383: =$D383*$F383 -> 0 | H383: =IF(OR($E383="g",$E383="ml"),$D383,0) -> 0 | I383: =IF($C383="Açaí",1,0) -> 0 | J383: =IF($C383="Banana",1,0) -> 0 | K383: =IF($C383="Whey Protein",1,0) -> 0 | L383: =IF(ISNUMBER(SEARCH("Copo",$C383)),1,0) -> 0
B384: =IF($C384="","",IFERROR(INDEX(Insumos_Categoria,MATCH($C384,Insumos_Ingrediente,0)),"")) | E384: =IF($C384="","",IFERROR(INDEX(Insumos_Unidade,MATCH($C384,Insumos_Ingrediente,0)),"")) | F384: =IFERROR(INDEX(Insumos_CustoUnit,MATCH($C384,Insumos_Ingrediente,0)),0) -> 0 | G384: =$D384*$F384 -> 0 | H384: =IF(OR($E384="g",$E384="ml"),$D384,0) -> 0 | I384: =IF($C384="Açaí",1,0) -> 0 | J384: =IF($C384="Banana",1,0) -> 0 | K384: =IF($C384="Whey Protein",1,0) -> 0 | L384: =IF(ISNUMBER(SEARCH("Copo",$C384)),1,0) -> 0
B385: =IF($C385="","",IFERROR(INDEX(Insumos_Categoria,MATCH($C385,Insumos_Ingrediente,0)),"")) | E385: =IF($C385="","",IFERROR(INDEX(Insumos_Unidade,MATCH($C385,Insumos_Ingrediente,0)),"")) | F385: =IFERROR(INDEX(Insumos_CustoUnit,MATCH($C385,Insumos_Ingrediente,0)),0) -> 0 | G385: =$D385*$F385 -> 0 | H385: =IF(OR($E385="g",$E385="ml"),$D385,0) -> 0 | I385: =IF($C385="Açaí",1,0) -> 0 | J385: =IF($C385="Banana",1,0) -> 0 | K385: =IF($C385="Whey Protein",1,0) -> 0 | L385: =IF(ISNUMBER(SEARCH("Copo",$C385)),1,0) -> 0
... B480: =IF($C480="","",IFERROR(INDEX(Insumos_Categoria,MATCH($C480,Insumos_Ingrediente,0)),"")) | E480: =IF($C480="","",IFERROR(INDEX(Insumos_Unidade,MATCH($C480,Insumos_Ingrediente,0)),"")) | F480: =IFERROR(INDEX(Insumos_CustoUnit,MATCH($C480,Insumos_Ingrediente,0)),0) -> 0 | G480: =$D480*$F480 -> 0 | H480: =IF(OR($E480="g",$E480="ml"),$D480,0) -> 0 | I480: =IF($C480="Açaí",1,0) -> 0 | J480: =IF($C480="Banana",1,0) -> 0 | K480: =IF($C480="Whey Protein",1,0) -> 0 | L480: =IF(ISNUMBER(SEARCH("Copo",$C480)),1,0) -> 0

Sheet Receitas
A1: 🧾 RECEITAS — Preço do Cardápio x Custo Real de Cada Produto
A2: 'Preço Praticado' já vem preenchido com o valor do seu cardápio — pode ajustar se mudar. As demais colunas calculam sozinhas, usando a loja selecionada em Configurações (célula B13).
A4: Produto | B4: Grupo (Cardápio) | C4: Preço Praticado (R$) | D4: Peso Total (g/ml) | E4: Custo Insumos (R$) | F4: Custo Insumos c/ Perdas (R$) | G4: Custo Fixo Rateado (R$) | H4: Custo Total Unitário (R$) | I4: Preço Sugerido (R$) | J4: CMV Real (%) | K4: Margem Real (%) | L4: Lucro Líquido Real (R$) | M4: Praticado − Sugerido (R$) | N4: Status
A5: Açaí em Ondas 200ml | B5: Açaí em Ondas & Receitas Fast | C5: 16.9 | D5: =IF($A5="","",SUMIFS(FichaTecnica_QtdGML,FichaTecnica_Produto,$A5)) -> 260 | E5: =IF($A5="","",SUMIFS(FichaTecnica_CustoTotal,FichaTecnica_Produto,$A5)) -> 4.1810308 | F5: =IF($A5="","",IFERROR($E5/(1-Perdas),$E5)) -> 4.310341 | G5: =IF($A5="","",IFERROR(INDEX(Rateio_CustoFixoPorVendaLinha,MATCH(LojaSelecionada,Rateio_LojasHeader,0)),0)) -> 7.4082778 | H5: =IF($A5="","",$F5+$G5) -> 11.718619 | I5: =IF($A5="","",IFERROR($H5/(1-MargemLiquidaDesejada-Impostos-TaxaCartao-Comissao),"Ajustar parâmetros")) -> 18.168401 | J5: =IF(OR($A5="",$C5=""),"",IFERROR($F5/$C5,"")) -> 0.25504976 | K5: =IF(OR($A5="",$C5=""),"",IFERROR(($C5-$H5-$C5*(Impostos+TaxaCartao+Comissao))/$C5,"")) -> 0.1015906 | L5: =IF(OR($A5="",$C5=""),"",$C5-$H5-$C5*(Impostos+TaxaCartao+Comissao)) -> 1.7168812 | M5: =IF(OR($A5="",$C5="",NOT(ISNUMBER($I5))),"",$C5-$I5) -> -1.2684012 | N5: =IF(OR($A5="",$K5=""),"",IF($K5>=MargemLiquidaDesejada,"🟢 Margem Saudável",IF($K5>=MargemLiquidaDesejada*0.8,"🟡 Atenção","🔴 Abaixo da Meta"))) -> 🔴 Abaixo da Meta
A6: Açaí em Ondas 300ml | B6: Açaí em Ondas & Receitas Fast | C6: 22.9 | D6: =IF($A6="","",SUMIFS(FichaTecnica_QtdGML,FichaTecnica_Produto,$A6)) -> 360 | E6: =IF($A6="","",SUMIFS(FichaTecnica_CustoTotal,FichaTecnica_Produto,$A6)) -> 5.8179508 | F6: =IF($A6="","",IFERROR($E6/(1-Perdas),$E6)) -> 5.9978874 | G6: =IF($A6="","",IFERROR(INDEX(Rateio_CustoFixoPorVendaLinha,MATCH(LojaSelecionada,Rateio_LojasHeader,0)),0)) -> 7.4082778 | H6: =IF($A6="","",$F6+$G6) -> 13.406165 | I6: =IF($A6="","",IFERROR($H6/(1-MargemLiquidaDesejada-Impostos-TaxaCartao-Comissao),"Ajustar parâmetros")) -> 20.784752 | J6: =IF(OR($A6="",$C6=""),"",IFERROR($F6/$C6,"")) -> 0.26191648 | K6: =IF(OR($A6="",$C6=""),"",IFERROR(($C6-$H6-$C6*(Impostos+TaxaCartao+Comissao))/$C6,"")) -> 0.20957794 | L6: =IF(OR($A6="",$C6=""),"",$C6-$H6-$C6*(Impostos+TaxaCartao+Comissao)) -> 4.7993348 | M6: =IF(OR($A6="",$C6="",NOT(ISNUMBER($I6))),"",$C6-$I6) -> 2.1152478 | N6: =IF(OR($A6="",$K6=""),"",IF($K6>=MargemLiquidaDesejada,"🟢 Margem Saudável",IF($K6>=MargemLiquidaDesejada*0.8,"🟡 Atenção","🔴 Abaixo da Meta"))) -> 🟢 Margem Saudável
A7: Açaí em Ondas 500ml | B7: Açaí em Ondas & Receitas Fast | C7: 29.9 | D7: =IF($A7="","",SUMIFS(FichaTecnica_QtdGML,FichaTecnica_Produto,$A7)) -> 560 | E7: =IF($A7="","",SUMIFS(FichaTecnica_CustoTotal,FichaTecnica_Produto,$A7)) -> 9.2178808 | F7: =IF($A7="","",IFERROR($E7/(1-Perdas),$E7)) -> 9.5029699 | G7: =IF($A7="","",IFERROR(INDEX(Rateio_CustoFixoPorVendaLinha,MATCH(LojaSelecionada,Rateio_LojasHeader,0)),0)) -> 7.4082778 | H7: =IF($A7="","",$F7+$G7) -> 16.911248 | I7: =IF($A7="","",IFERROR($H7/(1-MargemLiquidaDesejada-Impostos-TaxaCartao-Comissao),"Ajustar parâmetros")) -> 26.218989 | J7: =IF(OR($A7="",$C7=""),"",IFERROR($F7/$C7,"")) -> 0.31782508 | K7: =IF(OR($A7="",$C7=""),"",IFERROR(($C7-$H7-$C7*(Impostos+TaxaCartao+Comissao))/$C7,"")) -> 0.22940643 | L7: =IF(OR($A7="",$C7=""),"",$C7-$H7-$C7*(Impostos+TaxaCartao+Comissao)) -> 6.8592524 | M7: =IF(OR($A7="",$C7="",NOT(ISNUMBER($I7))),"",$C7-$I7) -> 3.6810114 | N7: =IF(OR($A7="",$K7=""),"",IF($K7>=MargemLiquidaDesejada,"🟢 Margem Saudável",IF($K7>=MargemLiquidaDesejada*0.8,"🟡 Atenção","🔴 Abaixo da Meta"))) -> 🟢 Margem Saudável
A8: Fast Classic 200ml | B8: Açaí em Ondas & Receitas Fast | C8: 16.9 | D8: =IF($A8="","",SUMIFS(FichaTecnica_QtdGML,FichaTecnica_Produto,$A8)) -> 290 | E8: =IF($A8="","",SUMIFS(FichaTecnica_CustoTotal,FichaTecnica_Produto,$A8)) -> 5.1875308 | F8: =IF($A8="","",IFERROR($E8/(1-Perdas),$E8)) -> 5.3479699 | G8: =IF($A8="","",IFERROR(INDEX(Rateio_CustoFixoPorVendaLinha,MATCH(LojaSelecionada,Rateio_LojasHeader,0)),0)) -> 7.4082778 | H8: =IF($A8="","",$F8+$G8) -> 12.756248 | I8: =IF($A8="","",IFERROR($H8/(1-MargemLiquidaDesejada-Impostos-TaxaCartao-Comissao),"Ajustar parâmetros")) -> 19.777128 | J8: =IF(OR($A8="",$C8=""),"",IFERROR($F8/$C8,"")) -> 0.31644792 | K8: =IF(OR($A8="",$C8=""),"",IFERROR(($C8-$H8-$C8*(Impostos+TaxaCartao+Comissao))/$C8,"")) -> 0.040192447 | L8: =IF(OR($A8="",$C8=""),"",$C8-$H8-$C8*(Impostos+TaxaCartao+Comissao)) -> 0.67925236 | M8: =IF(OR($A8="",$C8="",NOT(ISNUMBER($I8))),"",$C8-$I8) -> -2.8771281 | N8: =IF(OR($A8="",$K8=""),"",IF($K8>=MargemLiquidaDesejada,"🟢 Margem Saudável",IF($K8>=MargemLiquidaDesejada*0.8,"🟡 Atenção","🔴 Abaixo da Meta"))) -> 🔴 Abaixo da Meta
A9: Fast Classic 300ml | B9: Açaí em Ondas & Receitas Fast | C9: 22.9 | D9: =IF($A9="","",SUMIFS(FichaTecnica_QtdGML,FichaTecnica_Produto,$A9)) -> 390 | E9: =IF($A9="","",SUMIFS(FichaTecnica_CustoTotal,FichaTecnica_Produto,$A9)) -> 6.8244508 | F9: =IF($A9="","",IFERROR($E9/(1-Perdas),$E9)) -> 7.0355163 | G9: =IF($A9="","",IFERROR(INDEX(Rateio_CustoFixoPorVendaLinha,MATCH(LojaSelecionada,Rateio_LojasHeader,0)),0)) -> 7.4082778 | H9: =IF($A9="","",$F9+$G9) -> 14.443794 | I9: =IF($A9="","",IFERROR($H9/(1-MargemLiquidaDesejada-Impostos-TaxaCartao-Comissao),"Ajustar parâmetros")) -> 22.393479 | J9: =IF(OR($A9="",$C9=""),"",IFERROR($F9/$C9,"")) -> 0.30722778 | K9: =IF(OR($A9="",$C9=""),"",IFERROR(($C9-$H9-$C9*(Impostos+TaxaCartao+Comissao))/$C9,"")) -> 0.16426664 | L9: =IF(OR($A9="",$C9=""),"",$C9-$H9-$C9*(Impostos+TaxaCartao+Comissao)) -> 3.761706 | M9: =IF(OR($A9="",$C9="",NOT(ISNUMBER($I9))),"",$C9-$I9) -> 0.50652088 | N9: =IF(OR($A9="",$K9=""),"",IF($K9>=MargemLiquidaDesejada,"🟢 Margem Saudável",IF($K9>=MargemLiquidaDesejada*0.8,"🟡 Atenção","🔴 Abaixo da Meta"))) -> 🟢 Margem Saudável
A10: Fast Classic 500ml | B10: Açaí em Ondas & Receitas Fast | C10: 29.9 | D10: =IF($A10="","",SUMIFS(FichaTecnica_QtdGML,FichaTecnica_Produto,$A10)) -> 590 | E10: =IF($A10="","",SUMIFS(FichaTecnica_CustoTotal,FichaTecnica_Produto,$A10)) -> 10.224381 | F10: =IF($A10="","",IFERROR($E10/(1-Perdas),$E10)) -> 10.540599 | G10: =IF($A10="","",IFERROR(INDEX(Rateio_CustoFixoPorVendaLinha,MATCH(LojaSelecionada,Rateio_LojasHeader,0)),0)) -> 7.4082778 | H10: =IF($A10="","",$F10+$G10) -> 17.948877 | I10: =IF($A10="","",IFERROR($H10/(1-MargemLiquidaDesejada-Impostos-TaxaCartao-Comissao),"Ajustar parâmetros")) -> 27.827716 | J10: =IF(OR($A10="",$C10=""),"",IFERROR($F10/$C10,"")) -> 0.35252839 | K10: =IF(OR($A10="",$C10=""),"",IFERROR(($C10-$H10-$C10*(Impostos+TaxaCartao+Comissao))/$C10,"")) -> 0.19470313 | L10: =IF(OR($A10="",$C10=""),"",$C10-$H10-$C10*(Impostos+TaxaCartao+Comissao)) -> 5.8216235 | M10: =IF(OR($A10="",$C10="",NOT(ISNUMBER($I10))),"",$C10-$I10) -> 2.0722845 | N10: =IF(OR($A10="",$K10=""),"",IF($K10>=MargemLiquidaDesejada,"🟢 Margem Saudável",IF($K10>=MargemLiquidaDesejada*0.8,"🟡 Atenção","🔴 Abaixo da Meta"))) -> 🟢 Margem Saudável
A11: Power 200ml | B11: Açaí em Ondas & Receitas Fast | C11: 16.9 | D11: =IF($A11="","",SUMIFS(FichaTecnica_QtdGML,FichaTecnica_Produto,$A11)) -> 290 | E11: =IF($A11="","",SUMIFS(FichaTecnica_CustoTotal,FichaTecnica_Produto,$A11)) -> 4.8509308 | F11: =IF($A11="","",IFERROR($E11/(1-Perdas),$E11)) -> 5.0009596 | G11: =IF($A11="","",IFERROR(INDEX(Rateio_CustoFixoPorVendaLinha,MATCH(LojaSelecionada,Rateio_LojasHeader,0)),0)) -> 7.4082778 | H11: =IF($A11="","",$F11+$G11) -> 12.409237 | I11: =IF($A11="","",IFERROR($H11/(1-MargemLiquidaDesejada-Impostos-TaxaCartao-Comissao),"Ajustar parâmetros")) -> 19.239128 | J11: =IF(OR($A11="",$C11=""),"",IFERROR($F11/$C11,"")) -> 0.29591477 | K11: =IF(OR($A11="",$C11=""),"",IFERROR(($C11-$H11-$C11*(Impostos+TaxaCartao+Comissao))/$C11,"")) -> 0.060725602 | L11: =IF(OR($A11="",$C11=""),"",$C11-$H11-$C11*(Impostos+TaxaCartao+Comissao)) -> 1.0262627 | M11: =IF(OR($A11="",$C11="",NOT(ISNUMBER($I11))),"",$C11-$I11) -> -2.3391276 | N11: =IF(OR($A11="",$K11=""),"",IF($K11>=MargemLiquidaDesejada,"🟢 Margem Saudável",IF($K11>=MargemLiquidaDesejada*0.8,"🟡 Atenção","🔴 Abaixo da Meta"))) -> 🔴 Abaixo da Meta
A12: Power 300ml | B12: Açaí em Ondas & Receitas Fast | C12: 22.9 | D12: =IF($A12="","",SUMIFS(FichaTecnica_QtdGML,FichaTecnica_Produto,$A12)) -> 390 | E12: =IF($A12="","",SUMIFS(FichaTecnica_CustoTotal,FichaTecnica_Produto,$A12)) -> 6.4878508 | F12: =IF($A12="","",IFERROR($E12/(1-Perdas),$E12)) -> 6.6885059 | G12: =IF($A12="","",IFERROR(INDEX(Rateio_CustoFixoPorVendaLinha,MATCH(LojaSelecionada,Rateio_LojasHeader,0)),0)) -> 7.4082778 | H12: =IF($A12="","",$F12+$G12) -> 14.096784 | I12: =IF($A12="","",IFERROR($H12/(1-MargemLiquidaDesejada-Impostos-TaxaCartao-Comissao),"Ajustar parâmetros")) -> 21.855479 | J12: =IF(OR($A12="",$C12=""),"",IFERROR($F12/$C12,"")) -> 0.2920745 | K12: =IF(OR($A12="",$C12=""),"",IFERROR(($C12-$H12-$C12*(Impostos+TaxaCartao+Comissao))/$C12,"")) -> 0.17941992 | L12: =IF(OR($A12="",$C12=""),"",$C12-$H12-$C12*(Impostos+TaxaCartao+Comissao)) -> 4.1087163 | M12: =IF(OR($A12="",$C12="",NOT(ISNUMBER($I12))),"",$C12-$I12) -> 1.0445214 | N12: =IF(OR($A12="",$K12=""),"",IF($K12>=MargemLiquidaDesejada,"🟢 Margem Saudável",IF($K12>=MargemLiquidaDesejada*0.8,"🟡 Atenção","🔴 Abaixo da Meta"))) -> 🟢 Margem Saudável
A13: Power 500ml | B13: Açaí em Ondas & Receitas Fast | C13: 29.9 | D13: =IF($A13="","",SUMIFS(FichaTecnica_QtdGML,FichaTecnica_Produto,$A13)) -> 590 | E13: =IF($A13="","",SUMIFS(FichaTecnica_CustoTotal,FichaTecnica_Produto,$A13)) -> 9.8877808 | F13: =IF($A13="","",IFERROR($E13/(1-Perdas),$E13)) -> 10.193588 | G13: =IF($A13="","",IFERROR(INDEX(Rateio_CustoFixoPorVendaLinha,MATCH(LojaSelecionada,Rateio_LojasHeader,0)),0)) -> 7.4082778 | H13: =IF($A13="","",$F13+$G13) -> 17.601866 | I13: =IF($A13="","",IFERROR($H13/(1-MargemLiquidaDesejada-Impostos-TaxaCartao-Comissao),"Ajustar parâmetros")) -> 27.289715 | J13: =IF(OR($A13="",$C13=""),"",IFERROR($F13/$C13,"")) -> 0.34092269 | K13: =IF(OR($A13="",$C13=""),"",IFERROR(($C13-$H13-$C13*(Impostos+TaxaCartao+Comissao))/$C13,"")) -> 0.20630882 | L13: =IF(OR($A13="",$C13=""),"",$C13-$H13-$C13*(Impostos+TaxaCartao+Comissao)) -> 6.1686338 | M13: =IF(OR($A13="",$C13="",NOT(ISNUMBER($I13))),"",$C13-$I13) -> 2.610285 | N13: =IF(OR($A13="",$K13=""),"",IF($K13>=MargemLiquidaDesejada,"🟢 Margem Saudável",IF($K13>=MargemLiquidaDesejada*0.8,"🟡 Atenção","🔴 Abaixo da Meta"))) -> 🟢 Margem Saudável
A14: Choco Nuts 200ml | B14: Açaí em Ondas & Receitas Fast | C14: 16.9 | D14: =IF($A14="","",SUMIFS(FichaTecnica_QtdGML,FichaTecnica_Produto,$A14)) -> 290 | E14: =IF($A14="","",SUMIFS(FichaTecnica_CustoTotal,FichaTecnica_Produto,$A14)) -> 5.5371 | F14: =IF($A14="","",IFERROR($E14/(1-Perdas),$E14)) -> 5.7083505 | G14: =IF($A14="","",IFERROR(INDEX(Rateio_CustoFixoPorVendaLinha,MATCH(LojaSelecionada,Rateio_LojasHeader,0)),0)) -> 7.4082778 | H14: =IF($A14="","",$F14+$G14) -> 13.116628 | I14: =IF($A14="","",IFERROR($H14/(1-MargemLiquidaDesejada-Impostos-TaxaCartao-Comissao),"Ajustar parâmetros")) -> 20.335858 | J14: =IF(OR($A14="",$C14=""),"",IFERROR($F14/$C14,"")) -> 0.33777222 | K14: =IF(OR($A14="",$C14=""),"",IFERROR(($C14-$H14-$C14*(Impostos+TaxaCartao+Comissao))/$C14,"")) -> 0.018868148 | L14: =IF(OR($A14="",$C14=""),"",$C14-$H14-$C14*(Impostos+TaxaCartao+Comissao)) -> 0.31887171 | M14: =IF(OR($A14="",$C14="",NOT(ISNUMBER($I14))),"",$C14-$I14) -> -3.4358578 | N14: =IF(OR($A14="",$K14=""),"",IF($K14>=MargemLiquidaDesejada,"🟢 Margem Saudável",IF($K14>=MargemLiquidaDesejada*0.8,"🟡 Atenção","🔴 Abaixo da Meta"))) -> 🔴 Abaixo da Meta
A15: Choco Nuts 300ml | B15: Açaí em Ondas & Receitas Fast | C15: 22.9 | D15: =IF($A15="","",SUMIFS(FichaTecnica_QtdGML,FichaTecnica_Produto,$A15)) -> 390 | E15: =IF($A15="","",SUMIFS(FichaTecnica_CustoTotal,FichaTecnica_Produto,$A15)) -> 7.17402 | F15: =IF($A15="","",IFERROR($E15/(1-Perdas),$E15)) -> 7.3958969 | G15: =IF($A15="","",IFERROR(INDEX(Rateio_CustoFixoPorVendaLinha,MATCH(LojaSelecionada,Rateio_LojasHeader,0)),0)) -> 7.4082778 | H15: =IF($A15="","",$F15+$G15) -> 14.804175 | I15: =IF($A15="","",IFERROR($H15/(1-MargemLiquidaDesejada-Impostos-TaxaCartao-Comissao),"Ajustar parâmetros")) -> 22.952209 | J15: =IF(OR($A15="",$C15=""),"",IFERROR($F15/$C15,"")) -> 0.32296493 | K15: =IF(OR($A15="",$C15=""),"",IFERROR(($C15-$H15-$C15*(Impostos+TaxaCartao+Comissao))/$C15,"")) -> 0.14852949 | L15: =IF(OR($A15="",$C15=""),"",$C15-$H15-$C15*(Impostos+TaxaCartao+Comissao)) -> 3.4013253 | M15: =IF(OR($A15="",$C15="",NOT(ISNUMBER($I15))),"",$C15-$I15) -> -0.052208814 | N15: =IF(OR($A15="",$K15=""),"",IF($K15>=MargemLiquidaDesejada,"🟢 Margem Saudável",IF($K15>=MargemLiquidaDesejada*0.8,"🟡 Atenção","🔴 Abaixo da Meta"))) -> 🟡 Atenção
